[2023-08-22T11:45:06.035+0000] {processor.py:157} INFO - Started process (PID=41608) to work on /home/airflow/.local/lib/python3.7/site-packages/airflow/example_dags/example_sla_dag.py
[2023-08-22T11:45:06.061+0000] {processor.py:826} INFO - Processing file /home/airflow/.local/lib/python3.7/site-packages/airflow/example_dags/example_sla_dag.py for tasks to queue
[2023-08-22T11:45:06.103+0000] {logging_mixin.py:150} INFO - [2023-08-22T11:45:06.102+0000] {dagbag.py:541} INFO - Filling up the DagBag from /home/airflow/.local/lib/python3.7/site-packages/airflow/example_dags/example_sla_dag.py
[2023-08-22T11:45:06.870+0000] {processor.py:836} INFO - DAG(s) dict_keys(['example_sla_dag']) retrieved from /home/airflow/.local/lib/python3.7/site-packages/airflow/example_dags/example_sla_dag.py
[2023-08-22T11:45:08.455+0000] {logging_mixin.py:150} INFO - [2023-08-22T11:45:08.431+0000] {dag.py:2742} INFO - Sync 1 DAGs
[2023-08-22T11:45:10.043+0000] {logging_mixin.py:150} INFO - [2023-08-22T11:45:10.040+0000] {dag.py:3508} INFO - Setting next_dagrun for example_sla_dag to 2023-08-22T11:42:00+00:00, run_after=2023-08-22T11:44:00+00:00
[2023-08-22T12:00:43.124+0000] {processor.py:182} ERROR - Got an exception! Propagating...
Traceback (most recent call last):
  File "/home/airflow/.local/lib/python3.7/site-packages/sqlalchemy/engine/base.py", line 2138, in _handle_dbapi_exception
    util.raise_(exc_info[1], with_traceback=exc_info[2])
  File "/home/airflow/.local/lib/python3.7/site-packages/sqlalchemy/util/compat.py", line 211, in raise_
    raise exception
  File "/home/airflow/.local/lib/python3.7/site-packages/sqlalchemy/engine/base.py", line 1911, in _execute_context
    cursor, statement, parameters, context
  File "/home/airflow/.local/lib/python3.7/site-packages/sqlalchemy/engine/default.py", line 736, in do_execute
    cursor.execute(statement, parameters)
  File "/usr/local/lib/python3.7/encodings/utf_8.py", line 15, in decode
    def decode(input, errors='strict'):
  File "/home/airflow/.local/lib/python3.7/site-packages/airflow/dag_processing/manager.py", line 475, in _exit_gracefully
    sys.exit(os.EX_OK)
SystemExit: 0

During handling of the above exception, another exception occurred:

Traceback (most recent call last):
  File "/home/airflow/.local/lib/python3.7/site-packages/airflow/utils/session.py", line 36, in create_session
    yield session
  File "/home/airflow/.local/lib/python3.7/site-packages/airflow/utils/session.py", line 76, in wrapper
    return func(*args, session=session, **kwargs)
  File "/home/airflow/.local/lib/python3.7/site-packages/airflow/dag_processing/processor.py", line 890, in save_dag_to_db
    import_errors = DagBag._sync_to_db(dags=dags, processor_subdir=dag_directory, session=session)
  File "/home/airflow/.local/lib/python3.7/site-packages/airflow/utils/session.py", line 73, in wrapper
    return func(*args, **kwargs)
  File "/home/airflow/.local/lib/python3.7/site-packages/airflow/models/dagbag.py", line 659, in _sync_to_db
    for attempt in run_with_db_retries(logger=log):
  File "/home/airflow/.local/lib/python3.7/site-packages/tenacity/__init__.py", line 347, in __iter__
    do = self.iter(retry_state=retry_state)
  File "/home/airflow/.local/lib/python3.7/site-packages/tenacity/__init__.py", line 314, in iter
    return fut.result()
  File "/usr/local/lib/python3.7/concurrent/futures/_base.py", line 428, in result
    return self.__get_result()
  File "/usr/local/lib/python3.7/concurrent/futures/_base.py", line 384, in __get_result
    raise self._exception
  File "/home/airflow/.local/lib/python3.7/site-packages/airflow/models/dagbag.py", line 673, in _sync_to_db
    DAG.bulk_write_to_db(dags.values(), processor_subdir=processor_subdir, session=session)
  File "/home/airflow/.local/lib/python3.7/site-packages/airflow/utils/session.py", line 73, in wrapper
    return func(*args, **kwargs)
  File "/home/airflow/.local/lib/python3.7/site-packages/airflow/models/dag.py", line 2847, in bulk_write_to_db
    DagCode.bulk_sync_to_db(filelocs, session=session)
  File "/home/airflow/.local/lib/python3.7/site-packages/airflow/utils/session.py", line 73, in wrapper
    return func(*args, **kwargs)
  File "/home/airflow/.local/lib/python3.7/site-packages/airflow/models/dagcode.py", line 83, in bulk_sync_to_db
    .with_for_update(of=DagCode)
  File "/home/airflow/.local/lib/python3.7/site-packages/sqlalchemy/orm/query.py", line 2773, in all
    return self._iter().all()
  File "/home/airflow/.local/lib/python3.7/site-packages/sqlalchemy/orm/query.py", line 2919, in _iter
    execution_options={"_sa_orm_load_options": self.load_options},
  File "/home/airflow/.local/lib/python3.7/site-packages/sqlalchemy/orm/session.py", line 1717, in execute
    result = conn._execute_20(statement, params or {}, execution_options)
  File "/home/airflow/.local/lib/python3.7/site-packages/sqlalchemy/engine/base.py", line 1710, in _execute_20
    return meth(self, args_10style, kwargs_10style, execution_options)
  File "/home/airflow/.local/lib/python3.7/site-packages/sqlalchemy/sql/elements.py", line 335, in _execute_on_connection
    self, multiparams, params, execution_options
  File "/home/airflow/.local/lib/python3.7/site-packages/sqlalchemy/engine/base.py", line 1587, in _execute_clauseelement
    cache_hit=cache_hit,
  File "/home/airflow/.local/lib/python3.7/site-packages/sqlalchemy/engine/base.py", line 1954, in _execute_context
    e, statement, parameters, cursor, context
  File "/home/airflow/.local/lib/python3.7/site-packages/sqlalchemy/engine/base.py", line 2148, in _handle_dbapi_exception
    self.invalidate(e)
  File "/home/airflow/.local/lib/python3.7/site-packages/sqlalchemy/engine/base.py", line 748, in invalidate
    if self._still_open_and_dbapi_connection_is_valid:
  File "/home/airflow/.local/lib/python3.7/site-packages/sqlalchemy/engine/base.py", line 657, in _still_open_and_dbapi_connection_is_valid
    @property
  File "/home/airflow/.local/lib/python3.7/site-packages/airflow/dag_processing/manager.py", line 475, in _exit_gracefully
    sys.exit(os.EX_OK)
SystemExit: 0

During handling of the above exception, another exception occurred:

Traceback (most recent call last):
  File "/home/airflow/.local/lib/python3.7/site-packages/sqlalchemy/engine/base.py", line 1062, in _rollback_impl
    self.engine.dialect.do_rollback(self.connection)
  File "/home/airflow/.local/lib/python3.7/site-packages/sqlalchemy/engine/default.py", line 683, in do_rollback
    dbapi_connection.rollback()
psycopg2.OperationalError: no connection to the server


The above exception was the direct cause of the following exception:

Traceback (most recent call last):
  File "/home/airflow/.local/lib/python3.7/site-packages/airflow/dag_processing/processor.py", line 178, in _run_file_processor
    _handle_dag_file_processing()
  File "/home/airflow/.local/lib/python3.7/site-packages/airflow/dag_processing/processor.py", line 162, in _handle_dag_file_processing
    callback_requests=callback_requests,
  File "/home/airflow/.local/lib/python3.7/site-packages/airflow/utils/session.py", line 76, in wrapper
    return func(*args, session=session, **kwargs)
  File "/home/airflow/.local/lib/python3.7/site-packages/airflow/dag_processing/processor.py", line 857, in process_file
    pickle_dags=pickle_dags,
  File "/home/airflow/.local/lib/python3.7/site-packages/airflow/api_internal/internal_api_call.py", line 112, in wrapper
    return func(*args, **kwargs)
  File "/home/airflow/.local/lib/python3.7/site-packages/airflow/utils/session.py", line 76, in wrapper
    return func(*args, session=session, **kwargs)
  File "/usr/local/lib/python3.7/contextlib.py", line 130, in __exit__
    self.gen.throw(type, value, traceback)
  File "/home/airflow/.local/lib/python3.7/site-packages/airflow/utils/session.py", line 42, in create_session
    session.close()
  File "/home/airflow/.local/lib/python3.7/site-packages/sqlalchemy/orm/session.py", line 1816, in close
    self._close_impl(invalidate=False)
  File "/home/airflow/.local/lib/python3.7/site-packages/sqlalchemy/orm/session.py", line 1858, in _close_impl
    transaction.close(invalidate)
  File "/home/airflow/.local/lib/python3.7/site-packages/sqlalchemy/orm/session.py", line 926, in close
    transaction.close()
  File "/home/airflow/.local/lib/python3.7/site-packages/sqlalchemy/engine/base.py", line 2426, in close
    self._do_close()
  File "/home/airflow/.local/lib/python3.7/site-packages/sqlalchemy/engine/base.py", line 2649, in _do_close
    self._close_impl()
  File "/home/airflow/.local/lib/python3.7/site-packages/sqlalchemy/engine/base.py", line 2635, in _close_impl
    self._connection_rollback_impl()
  File "/home/airflow/.local/lib/python3.7/site-packages/sqlalchemy/engine/base.py", line 2627, in _connection_rollback_impl
    self.connection._rollback_impl()
  File "/home/airflow/.local/lib/python3.7/site-packages/sqlalchemy/engine/base.py", line 1064, in _rollback_impl
    self._handle_dbapi_exception(e, None, None, None, None)
  File "/home/airflow/.local/lib/python3.7/site-packages/sqlalchemy/engine/base.py", line 2135, in _handle_dbapi_exception
    sqlalchemy_exception, with_traceback=exc_info[2], from_=e
  File "/home/airflow/.local/lib/python3.7/site-packages/sqlalchemy/util/compat.py", line 211, in raise_
    raise exception
  File "/home/airflow/.local/lib/python3.7/site-packages/sqlalchemy/engine/base.py", line 1062, in _rollback_impl
    self.engine.dialect.do_rollback(self.connection)
  File "/home/airflow/.local/lib/python3.7/site-packages/sqlalchemy/engine/default.py", line 683, in do_rollback
    dbapi_connection.rollback()
sqlalchemy.exc.OperationalError: (psycopg2.OperationalError) no connection to the server

(Background on this error at: https://sqlalche.me/e/14/e3q8)
